Workbook

Sheet Dashboard y Gráficos
A1: MONITOREO DE METALES PRECIOSOS: ORO Y PLATA EN PESOS COLOMBIANOS (COP) | P1: Fecha | Q1: Oro (COP/g) | R1: Plata (COP/g)
P2: =IF(1<=$I$8, INDEX('Precios Diarios'!$A$2:$A$531, $G$8 - 1 + 1 - 1), NA()) | Q2: =IF(1<=$I$8, INDEX('Precios Diarios'!$E$2:$E$531, $G$8 - 1 + 1 - 1), NA()) | R2: =IF(1<=$I$8, INDEX('Precios Diarios'!$F$2:$F$531, $G$8 - 1 + 1 - 1), NA())
A3: ÚLTIMA FECHA | D3: ORO (COP/g) | G3: PLATA (COP/g) | J3: TRM (USD/COP) | M3: VAR. DÍA ORO | P3: =IF(2<=$I$8, INDEX('Precios Diarios'!$A$2:$A$531, $G$8 - 1 + 2 - 1), NA()) | Q3: =IF(2<=$I$8, INDEX('Precios Diarios'!$E$2:$E$531, $G$8 - 1 + 2 - 1), NA()) | R3: =IF(2<=$I$8, INDEX('Precios Diarios'!$F$2:$F$531, $G$8 - 1 + 2 - 1), NA())
A4: ='Precios Diarios'!A531 | D4: ='Precios Diarios'!E531 | G4: ='Precios Diarios'!F531 | J4: ='Precios Diarios'!D531 | M4: ='Precios Diarios'!G531 | P4: =IF(3<=$I$8, INDEX('Precios Diarios'!$A$2:$A$531, $G$8 - 1 + 3 - 1), NA()) | Q4: =IF(3<=$I$8, INDEX('Precios Diarios'!$E$2:$E$531, $G$8 - 1 + 3 - 1), NA()) | R4: =IF(3<=$I$8, INDEX('Precios Diarios'!$F$2:$F$531, $G$8 - 1 + 3 - 1), NA())
P5: =IF(4<=$I$8, INDEX('Precios Diarios'!$A$2:$A$531, $G$8 - 1 + 4 - 1), NA()) | Q5: =IF(4<=$I$8, INDEX('Precios Diarios'!$E$2:$E$531, $G$8 - 1 + 4 - 1), NA()) | R5: =IF(4<=$I$8, INDEX('Precios Diarios'!$F$2:$F$531, $G$8 - 1 + 4 - 1), NA())
P6: =IF(5<=$I$8, INDEX('Precios Diarios'!$A$2:$A$531, $G$8 - 1 + 5 - 1), NA()) | Q6: =IF(5<=$I$8, INDEX('Precios Diarios'!$E$2:$E$531, $G$8 - 1 + 5 - 1), NA()) | R6: =IF(5<=$I$8, INDEX('Precios Diarios'!$F$2:$F$531, $G$8 - 1 + 5 - 1), NA())
A7: SELECCIÓN DE PERÍODO A GRAFICAR: | P7: =IF(6<=$I$8, INDEX('Precios Diarios'!$A$2:$A$531, $G$8 - 1 + 6 - 1), NA()) | Q7: =IF(6<=$I$8, INDEX('Precios Diarios'!$E$2:$E$531, $G$8 - 1 + 6 - 1), NA()) | R7: =IF(6<=$I$8, INDEX('Precios Diarios'!$F$2:$F$531, $G$8 - 1 + 6 - 1), NA())
A8: Todo el Historial (Desde 2025) | E8: =IF(A8="Año 2025", DATE(2025,1,1), IF(A8="Año 2026", DATE(2026,1,1), IF(A8="Últimos 90 Días", TODAY()-90, IF(A8="Últimos 30 Días", TODAY()-30, DATE(2025,1,1))))) | F8: =IF(A8="Año 2025", DATE(2025,12,31), IF(A8="Año 2026", DATE(2026,12,31), TODAY())) | G8: =IFERROR(MATCH(E8, 'Precios Diarios'!$A$2:$A$531, 1), 1) + 1 | H8: =IFERROR(MATCH(F8, 'Precios Diarios'!$A$2:$A$531, 1), 530) + 1 | I8: =MAX(1, H8 - G8 + 1) | P8: =IF(7<=$I$8, INDEX('Precios Diarios'!$A$2:$A$531, $G$8 - 1 + 7 - 1), NA()) | Q8: =IF(7<=$I$8, INDEX('Precios Diarios'!$E$2:$E$531, $G$8 - 1 + 7 - 1), NA()) | R8: =IF(7<=$I$8, INDEX('Precios Diarios'!$F$2:$F$531, $G$8 - 1 + 7 - 1), NA())
A9: Nota: Para cambiar el período use A8. Para ver precios exactos al pasar el cursor, abra 'index.html'. | P9: =IF(8<=$I$8, INDEX('Precios Diarios'!$A$2:$A$531, $G$8 - 1 + 8 - 1), NA()) | Q9: =IF(8<=$I$8, INDEX('Precios Diarios'!$E$2:$E$531, $G$8 - 1 + 8 - 1), NA()) | R9: =IF(8<=$I$8, INDEX('Precios Diarios'!$F$2:$F$531, $G$8 - 1 + 8 - 1), NA())
P10: =IF(9<=$I$8, INDEX('Precios Diarios'!$A$2:$A$531, $G$8 - 1 + 9 - 1), NA()) | Q10: =IF(9<=$I$8, INDEX('Precios Diarios'!$E$2:$E$531, $G$8 - 1 + 9 - 1), NA()) | R10: =IF(9<=$I$8, INDEX('Precios Diarios'!$F$2:$F$531, $G$8 - 1 + 9 - 1), NA())
P11: =IF(10<=$I$8, INDEX('Precios Diarios'!$A$2:$A$531, $G$8 - 1 + 10 - 1), NA()) | Q11: =IF(10<=$I$8, INDEX('Precios Diarios'!$E$2:$E$531, $G$8 - 1 + 10 - 1), NA()) | R11: =IF(10<=$I$8, INDEX('Precios Diarios'!$F$2:$F$531, $G$8 - 1 + 10 - 1), NA())
P12: =IF(11<=$I$8, INDEX('Precios Diarios'!$A$2:$A$531, $G$8 - 1 + 11 - 1), NA()) | Q12: =IF(11<=$I$8, INDEX('Precios Diarios'!$E$2:$E$531, $G$8 - 1 + 11 - 1), NA()) | R12: =IF(11<=$I$8, INDEX('Precios Diarios'!$F$2:$F$531, $G$8 - 1 + 11 - 1), NA())
P13: =IF(12<=$I$8, INDEX('Precios Diarios'!$A$2:$A$531, $G$8 - 1 + 12 - 1), NA()) | Q13: =IF(12<=$I$8, INDEX('Precios Diarios'!$E$2:$E$531, $G$8 - 1 + 12 - 1), NA()) | R13: =IF(12<=$I$8, INDEX('Precios Diarios'!$F$2:$F$531, $G$8 - 1 + 12 - 1), NA())
P14: =IF(13<=$I$8, INDEX('Precios Diarios'!$A$2:$A$531, $G$8 - 1 + 13 - 1), NA()) | Q14: =IF(13<=$I$8, INDEX('Precios Diarios'!$E$2:$E$531, $G$8 - 1 + 13 - 1), NA()) | R14: =IF(13<=$I$8, INDEX('Precios Diarios'!$F$2:$F$531, $G$8 - 1 + 13 - 1), NA())
P15: =IF(14<=$I$8, INDEX('Precios Diarios'!$A$2:$A$531, $G$8 - 1 + 14 - 1), NA()) | Q15: =IF(14<=$I$8, INDEX('Precios Diarios'!$E$2:$E$531, $G$8 - 1 + 14 - 1), NA()) | R15: =IF(14<=$I$8, INDEX('Precios Diarios'!$F$2:$F$531, $G$8 - 1 + 14 - 1), NA())
P16: =IF(15<=$I$8, INDEX('Precios Diarios'!$A$2:$A$531, $G$8 - 1 + 15 - 1), NA()) | Q16: =IF(15<=$I$8, INDEX('Precios Diarios'!$E$2:$E$531, $G$8 - 1 + 15 - 1), NA()) | R16: =IF(15<=$I$8, INDEX('Precios Diarios'!$F$2:$F$531, $G$8 - 1 + 15 - 1), NA())
P17: =IF(16<=$I$8, INDEX('Precios Diarios'!$A$2:$A$531, $G$8 - 1 + 16 - 1), NA()) | Q17: =IF(16<=$I$8, INDEX('Precios Diarios'!$E$2:$E$531, $G$8 - 1 + 16 - 1), NA()) | R17: =IF(16<=$I$8, INDEX('Precios Diarios'!$F$2:$F$531, $G$8 - 1 + 16 - 1), NA())
P18: =IF(17<=$I$8, INDEX('Precios Diarios'!$A$2:$A$531, $G$8 - 1 + 17 - 1), NA()) | Q18: =IF(17<=$I$8, INDEX('Precios Diarios'!$E$2:$E$531, $G$8 - 1 + 17 - 1), NA()) | R18: =IF(17<=$I$8, INDEX('Precios Diarios'!$F$2:$F$531, $G$8 - 1 + 17 - 1), NA())
P19: =IF(18<=$I$8, INDEX('Precios Diarios'!$A$2:$A$531, $G$8 - 1 + 18 - 1), NA()) | Q19: =IF(18<=$I$8, INDEX('Precios Diarios'!$E$2:$E$531, $G$8 - 1 + 18 - 1), NA()) | R19: =IF(18<=$I$8, INDEX('Precios Diarios'!$F$2:$F$531, $G$8 - 1 + 18 - 1), NA())
P20: =IF(19<=$I$8, INDEX('Precios Diarios'!$A$2:$A$531, $G$8 - 1 + 19 - 1), NA()) | Q20: =IF(19<=$I$8, INDEX('Precios Diarios'!$E$2:$E$531, $G$8 - 1 + 19 - 1), NA()) | R20: =IF(19<=$I$8, INDEX('Precios Diarios'!$F$2:$F$531, $G$8 - 1 + 19 - 1), NA())
P21: =IF(20<=$I$8, INDEX('Precios Diarios'!$A$2:$A$531, $G$8 - 1 + 20 - 1), NA()) | Q21: =IF(20<=$I$8, INDEX('Precios Diarios'!$E$2:$E$531, $G$8 - 1 + 20 - 1), NA()) | R21: =IF(20<=$I$8, INDEX('Precios Diarios'!$F$2:$F$531, $G$8 - 1 + 20 - 1), NA())
P22: =IF(21<=$I$8, INDEX('Precios Diarios'!$A$2:$A$531, $G$8 - 1 + 21 - 1), NA()) | Q22: =IF(21<=$I$8, INDEX('Precios Diarios'!$E$2:$E$531, $G$8 - 1 + 21 - 1), NA()) | R22: =IF(21<=$I$8, INDEX('Precios Diarios'!$F$2:$F$531, $G$8 - 1 + 21 - 1), NA())
P23: =IF(22<=$I$8, INDEX('Precios Diarios'!$A$2:$A$531, $G$8 - 1 + 22 - 1), NA()) | Q23: =IF(22<=$I$8, INDEX('Precios Diarios'!$E$2:$E$531, $G$8 - 1 + 22 - 1), NA()) | R23: =IF(22<=$I$8, INDEX('Precios Diarios'!$F$2:$F$531, $G$8 - 1 + 22 - 1), NA())
P24: =IF(23<=$I$8, INDEX('Precios Diarios'!$A$2:$A$531, $G$8 - 1 + 23 - 1), NA()) | Q24: =IF(23<=$I$8, INDEX('Precios Diarios'!$E$2:$E$531, $G$8 - 1 + 23 - 1), NA()) | R24: =IF(23<=$I$8, INDEX('Precios Diarios'!$F$2:$F$531, $G$8 - 1 + 23 - 1), NA())
P25: =IF(24<=$I$8, INDEX('Precios Diarios'!$A$2:$A$531, $G$8 - 1 + 24 - 1), NA()) | Q25: =IF(24<=$I$8, INDEX('Precios Diarios'!$E$2:$E$531, $G$8 - 1 + 24 - 1), NA()) | R25: =IF(24<=$I$8, INDEX('Precios Diarios'!$F$2:$F$531, $G$8 - 1 + 24 - 1), NA())
P26: =IF(25<=$I$8, INDEX('Precios Diarios'!$A$2:$A$531, $G$8 - 1 + 25 - 1), NA()) | Q26: =IF(25<=$I$8, INDEX('Precios Diarios'!$E$2:$E$531, $G$8 - 1 + 25 - 1), NA()) | R26: =IF(25<=$I$8, INDEX('Precios Diarios'!$F$2:$F$531, $G$8 - 1 + 25 - 1), NA())
P27: =IF(26<=$I$8, INDEX('Precios Diarios'!$A$2:$A$531, $G$8 - 1 + 26 - 1), NA()) | Q27: =IF(26<=$I$8, INDEX('Precios Diarios'!$E$2:$E$531, $G$8 - 1 + 26 - 1), NA()) | R27: =IF(26<=$I$8, INDEX('Precios Diarios'!$F$2:$F$531, $G$8 - 1 + 26 - 1), NA())
P28: =IF(27<=$I$8, INDEX('Precios Diarios'!$A$2:$A$531, $G$8 - 1 + 27 - 1), NA()) | Q28: =IF(27<=$I$8, INDEX('Precios Diarios'!$E$2:$E$531, $G$8 - 1 + 27 - 1), NA()) | R28: =IF(27<=$I$8, INDEX('Precios Diarios'!$F$2:$F$531, $G$8 - 1 + 27 - 1), NA())
P29: =IF(28<=$I$8, INDEX('Precios Diarios'!$A$2:$A$531, $G$8 - 1 + 28 - 1), NA()) | Q29: =IF(28<=$I$8, INDEX('Precios Diarios'!$E$2:$E$531, $G$8 - 1 + 28 - 1), NA()) | R29: =IF(28<=$I$8, INDEX('Precios Diarios'!$F$2:$F$531, $G$8 - 1 + 28 - 1), NA())
P30: =IF(29<=$I$8, INDEX('Precios Diarios'!$A$2:$A$531, $G$8 - 1 + 29 - 1), NA()) | Q30: =IF(29<=$I$8, INDEX('Precios Diarios'!$E$2:$E$531, $G$8 - 1 + 29 - 1), NA()) | R30: =IF(29<=$I$8, INDEX('Precios Diarios'!$F$2:$F$531, $G$8 - 1 + 29 - 1), NA())
P31: =IF(30<=$I$8, INDEX('Precios Diarios'!$A$2:$A$531, $G$8 - 1 + 30 - 1), NA()) | Q31: =IF(30<=$I$8, INDEX('Precios Diarios'!$E$2:$E$531, $G$8 - 1 + 30 - 1), NA()) | R31: =IF(30<=$I$8, INDEX('Precios Diarios'!$F$2:$F$531, $G$8 - 1 + 30 - 1), NA())
P32: =IF(31<=$I$8, INDEX('Precios Diarios'!$A$2:$A$531, $G$8 - 1 + 31 - 1), NA()) | Q32: =IF(31<=$I$8, INDEX('Precios Diarios'!$E$2:$E$531, $G$8 - 1 + 31 - 1), NA()) | R32: =IF(31<=$I$8, INDEX('Precios Diarios'!$F$2:$F$531, $G$8 - 1 + 31 - 1), NA())
P33: =IF(32<=$I$8, INDEX('Precios Diarios'!$A$2:$A$531, $G$8 - 1 + 32 - 1), NA()) | Q33: =IF(32<=$I$8, INDEX('Precios Diarios'!$E$2:$E$531, $G$8 - 1 + 32 - 1), NA()) | R33: =IF(32<=$I$8, INDEX('Precios Diarios'!$F$2:$F$531, $G$8 - 1 + 32 - 1), NA())
P34: =IF(33<=$I$8, INDEX('Precios Diarios'!$A$2:$A$531, $G$8 - 1 + 33 - 1), NA()) | Q34: =IF(33<=$I$8, INDEX('Precios Diarios'!$E$2:$E$531, $G$8 - 1 + 33 - 1), NA()) | R34: =IF(33<=$I$8, INDEX('Precios Diarios'!$F$2:$F$531, $G$8 - 1 + 33 - 1), NA())
P35: =IF(34<=$I$8, INDEX('Precios Diarios'!$A$2:$A$531, $G$8 - 1 + 34 - 1), NA()) | Q35: =IF(34<=$I$8, INDEX('Precios Diarios'!$E$2:$E$531, $G$8 - 1 + 34 - 1), NA()) | R35: =IF(34<=$I$8, INDEX('Precios Diarios'!$F$2:$F$531, $G$8 - 1 + 34 - 1), NA())
P36: =IF(35<=$I$8, INDEX('Precios Diarios'!$A$2:$A$531, $G$8 - 1 + 35 - 1), NA()) | Q36: =IF(35<=$I$8, INDEX('Precios Diarios'!$E$2:$E$531, $G$8 - 1 + 35 - 1), NA()) | R36: =IF(35<=$I$8, INDEX('Precios Diarios'!$F$2:$F$531, $G$8 - 1 + 35 - 1), NA())
P37: =IF(36<=$I$8, INDEX('Precios Diarios'!$A$2:$A$531, $G$8 - 1 + 36 - 1), NA()) | Q37: =IF(36<=$I$8, INDEX('Precios Diarios'!$E$2:$E$531, $G$8 - 1 + 36 - 1), NA()) | R37: =IF(36<=$I$8, INDEX('Precios Diarios'!$F$2:$F$531, $G$8 - 1 + 36 - 1), NA())
P38: =IF(37<=$I$8, INDEX('Precios Diarios'!$A$2:$A$531, $G$8 - 1 + 37 - 1), NA()) | Q38: =IF(37<=$I$8, INDEX('Precios Diarios'!$E$2:$E$531, $G$8 - 1 + 37 - 1), NA()) | R38: =IF(37<=$I$8, INDEX('Precios Diarios'!$F$2:$F$531, $G$8 - 1 + 37 - 1), NA())
P39: =IF(38<=$I$8, INDEX('Precios Diarios'!$A$2:$A$531, $G$8 - 1 + 38 - 1), NA()) | Q39: =IF(38<=$I$8, INDEX('Precios Diarios'!$E$2:$E$531, $G$8 - 1 + 38 - 1), NA()) | R39: =IF(38<=$I$8, INDEX('Precios Diarios'!$F$2:$F$531, $G$8 - 1 + 38 - 1), NA())
P40: =IF(39<=$I$8, INDEX('Precios Diarios'!$A$2:$A$531, $G$8 - 1 + 39 - 1), NA()) | Q40: =IF(39<=$I$8, INDEX('Precios Diarios'!$E$2:$E$531, $G$8 - 1 + 39 - 1), NA()) | R40: =IF(39<=$I$8, INDEX('Precios Diarios'!$F$2:$F$531, $G$8 - 1 + 39 - 1), NA())
...

Sheet Precios Diarios
A1: Fecha | B1: Oro (USD/oz) | C1: Plata (USD/oz) | D1: TRM (USD/COP) | E1: Oro (COP/g) | F1: Plata (COP/g) | G1: Var. Oro % | H1: Var. Plata %
A2: 45659 | B2: 2669 | C2: 29.622 | D2: 4403.1699 | E2: =ROUND((B2/31.1034768)*D2, 2) | F2: =ROUND((C2/31.1034768)*D2, 2) | G2: 0 | H2: 0
A3: 45660 | B3: 2654.7 | C3: 29.806 | D3: 4382.3501 | E3: =ROUND((B3/31.1034768)*D3, 2) | F3: =ROUND((C3/31.1034768)*D3, 2) | G3: =IFERROR((E3-E2)/E2, 0) | H3: =IFERROR((F3-F2)/F2, 0)
A4: 45663 | B4: 2647.3999 | C4: 30.341999 | D4: 4319.5503 | E4: =ROUND((B4/31.1034768)*D4, 2) | F4: =ROUND((C4/31.1034768)*D4, 2) | G4: =IFERROR((E4-E3)/E3, 0) | H4: =IFERROR((F4-F3)/F3, 0)
A5: 45664 | B5: 2665.3999 | C5: 30.447001 | D5: 4338.25 | E5: =ROUND((B5/31.1034768)*D5, 2) | F5: =ROUND((C5/31.1034768)*D5, 2) | G5: =IFERROR((E5-E4)/E4, 0) | H5: =IFERROR((F5-F4)/F4, 0)
A6: 45665 | B6: 2672.3999 | C6: 30.452 | D6: 4335.5801 | E6: =ROUND((B6/31.1034768)*D6, 2) | F6: =ROUND((C6/31.1034768)*D6, 2) | G6: =IFERROR((E6-E5)/E5, 0) | H6: =IFERROR((F6-F5)/F5, 0)
A7: 45666 | B7: 2690.8 | C7: 30.791 | D7: 4325 | E7: =ROUND((B7/31.1034768)*D7, 2) | F7: =ROUND((C7/31.1034768)*D7, 2) | G7: =IFERROR((E7-E6)/E6, 0) | H7: =IFERROR((F7-F6)/F6, 0)
A8: 45667 | B8: 2715 | C8: 31.091 | D8: 4330.3901 | E8: =ROUND((B8/31.1034768)*D8, 2) | F8: =ROUND((C8/31.1034768)*D8, 2) | G8: =IFERROR((E8-E7)/E7, 0) | H8: =IFERROR((F8-F7)/F7, 0)
A9: 45670 | B9: 2678.6001 | C9: 30.091 | D9: 4300.2974 | E9: =ROUND((B9/31.1034768)*D9, 2) | F9: =ROUND((C9/31.1034768)*D9, 2) | G9: =IFERROR((E9-E8)/E8, 0) | H9: =IFERROR((F9-F8)/F8, 0)
A10: 45671 | B10: 2682.3 | C10: 30.132 | D10: 4304.75 | E10: =ROUND((B10/31.1034768)*D10, 2) | F10: =ROUND((C10/31.1034768)*D10, 2) | G10: =IFERROR((E10-E9)/E9, 0) | H10: =IFERROR((F10-F9)/F9, 0)
A11: 45672 | B11: 2717.8 | C11: 31.319 | D11: 4284.7002 | E11: =ROUND((B11/31.1034768)*D11, 2) | F11: =ROUND((C11/31.1034768)*D11, 2) | G11: =IFERROR((E11-E10)/E10, 0) | H11: =IFERROR((F11-F10)/F10, 0)
A12: 45673 | B12: 2750.8999 | C12: 31.523001 | D12: 4301.1899 | E12: =ROUND((B12/31.1034768)*D12, 2) | F12: =ROUND((C12/31.1034768)*D12, 2) | G12: =IFERROR((E12-E11)/E11, 0) | H12: =IFERROR((F12-F11)/F11, 0)
A13: 45674 | B13: 2748.7 | C13: 30.951 | D13: 4340 | E13: =ROUND((B13/31.1034768)*D13, 2) | F13: =ROUND((C13/31.1034768)*D13, 2) | G13: =IFERROR((E13-E12)/E12, 0) | H13: =IFERROR((F13-F12)/F12, 0)
A14: 45677 | B14: 2748.7 | C14: 30.951 | D14: 4297.4141 | E14: =ROUND((B14/31.1034768)*D14, 2) | F14: =ROUND((C14/31.1034768)*D14, 2) | G14: =IFERROR((E14-E13)/E13, 0) | H14: =IFERROR((F14-F13)/F13, 0)
... A531: 46325 | B531: 4017.6001 | C531: 51.535 | D531: 3166.99 | E531: =ROUND((B531/31.1034768)*D531, 2) | F531: =ROUND((C531/31.1034768)*D531, 2) | G531: =IFERROR((E531-E530)/E530, 0) | H531: =IFERROR((F531-F530)/F530, 0)
